Outputs (Seed=227)/Matching Engine Output (Buy equal to Sell).txt
D:\Athul\Quant Development\Matching Engine>g++ matching_engine.cpp -o server.exe -lws2_32 && server.exe
1. Buy ID: 8,   Sell ID: 5,     Price: 101,     Quantity: 50,   Timestamp: Mon Jul 24 12:29:48 2023
Total Trades = 1
Engine Profit = 0
2. Buy ID: 9,   Sell ID: 6,     Price: 101.75,  Quantity: 100,  Timestamp: Mon Jul 24 12:29:48 2023
3. Buy ID: 8,   Sell ID: 8,     Price: 101,     Quantity: 50,   Timestamp: Mon Jul 24 12:29:48 2023
4. Buy ID: 13,  Sell ID: 10,    Price: 102,     Quantity: 50,   Timestamp: Mon Jul 24 12:29:48 2023
5. Buy ID: 15,  Sell ID: 11,    Price: 101,     Quantity: 50,   Timestamp: Mon Jul 24 12:29:48 2023
6. Buy ID: 16,  Sell ID: 14,    Price: 100.25,  Quantity: 25,   Timestamp: Mon Jul 24 12:29:48 2023
7. Buy ID: 17,  Sell ID: 16,    Price: 100.75,  Quantity: 25,   Timestamp: Mon Jul 24 12:29:49 2023
8. Buy ID: 23,  Sell ID: 22,    Price: 101.25,  Quantity: 75,   Timestamp: Mon Jul 24 12:29:49 2023
9. Buy ID: 36,  Sell ID: 34,    Price: 100.5,   Quantity: 50,   Timestamp: Mon Jul 24 12:29:49 2023
10. Buy ID: 38,         Sell ID: 35,    Price: 101.25,  Quantity: 75,   Timestamp: Mon Jul 24 12:29:49 2023
11. Buy ID: 40,         Sell ID: 33,    Price: 100,     Quantity: 25,   Timestamp: Mon Jul 24 12:29:49 2023
12. Buy ID: 39,         Sell ID: 37,    Price: 100.5,   Quantity: 50,   Timestamp: Mon Jul 24 12:29:49 2023
13. Buy ID: 45,         Sell ID: 51,    Price: 101.75,  Quantity: 25,   Timestamp: Mon Jul 24 12:29:50 2023
14. Buy ID: 44,         Sell ID: 53,    Price: 101.5,   Quantity: 50,   Timestamp: Mon Jul 24 12:29:50 2023
15. Buy ID: 46,         Sell ID: 54,    Price: 101,     Quantity: 50,   Timestamp: Mon Jul 24 12:29:50 2023
16. Buy ID: 47,         Sell ID: 57,    Price: 101,     Quantity: 75,   Timestamp: Mon Jul 24 12:29:50 2023
17. Buy ID: 54,         Sell ID: 72,    Price: 101.5,   Quantity: 50,   Timestamp: Mon Jul 24 12:29:50 2023
18. Buy ID: 63,         Sell ID: 80,    Price: 101.25,  Quantity: 25,   Timestamp: Mon Jul 24 12:29:50 2023
19. Buy ID: 67,         Sell ID: 82,    Price: 102,     Quantity: 25,   Timestamp: Mon Jul 24 12:29:50 2023
20. Buy ID: 79,         Sell ID: 99,    Price: 100.75,  Quantity: 25,   Timestamp: Mon Jul 24 12:29:51 2023
21. Buy ID: 81,         Sell ID: 100,   Price: 101.25,  Quantity: 50,   Timestamp: Mon Jul 24 12:29:51 2023
22. Buy ID: 84,         Sell ID: 101,   Price: 100.75,  Quantity: 25,   Timestamp: Mon Jul 24 12:29:51 2023
23. Buy ID: 86,         Sell ID: 100,   Price: 101.25,  Quantity: 50,   Timestamp: Mon Jul 24 12:29:51 2023
24. Buy ID: 88,         Sell ID: 99,    Price: 100.75,  Quantity: 25,   Timestamp: Mon Jul 24 12:29:51 2023
25. Buy ID: 88,         Sell ID: 104,   Price: 100.75,  Quantity: 25,   Timestamp: Mon Jul 24 12:29:51 2023
26. Buy ID: 93,         Sell ID: 109,   Price: 100,     Quantity: 75,   Timestamp: Mon Jul 24 12:29:51 2023
27. Buy ID: 96,         Sell ID: 113,   Price: 102,     Quantity: 25,   Timestamp: Mon Jul 24 12:29:51 2023
28. Buy ID: 95,         Sell ID: 114,   Price: 100.75,  Quantity: 50,   Timestamp: Mon Jul 24 12:29:51 2023
29. Buy ID: 102,        Sell ID: 119,   Price: 101,     Quantity: 25,   Timestamp: Mon Jul 24 12:29:52 2023
30. Buy ID: 105,        Sell ID: 122,   Price: 100,     Quantity: 25,   Timestamp: Mon Jul 24 12:29:52 2023
31. Buy ID: 106,        Sell ID: 121,   Price: 101,     Quantity: 25,   Timestamp: Mon Jul 24 12:29:52 2023
32. Buy ID: 105,        Sell ID: 123,   Price: 100,     Quantity: 25,   Timestamp: Mon Jul 24 12:29:52 2023
33. Buy ID: 104,        Sell ID: 125,   Price: 100.75,  Quantity: 25,   Timestamp: Mon Jul 24 12:29:52 2023
34. Buy ID: 109,        Sell ID: 126,   Price: 101.5,   Quantity: 50,   Timestamp: Mon Jul 24 12:29:52 2023
35. Buy ID: 117,        Sell ID: 134,   Price: 100.25,  Quantity: 25,   Timestamp: Mon Jul 24 12:29:52 2023
36. Buy ID: 118,        Sell ID: 137,   Price: 100.5,   Quantity: 50,   Timestamp: Mon Jul 24 12:29:52 2023
37. Buy ID: 122,        Sell ID: 138,   Price: 101.25,  Quantity: 25,   Timestamp: Mon Jul 24 12:29:52 2023
38. Buy ID: 131,        Sell ID: 148,   Price: 100.25,  Quantity: 25,   Timestamp: Mon Jul 24 12:29:52 2023
39. Buy ID: 130,        Sell ID: 148,   Price: 100.25,  Quantity: 50,   Timestamp: Mon Jul 24 12:29:52 2023
40. Buy ID: 133,        Sell ID: 150,   Price: 101.75,  Quantity: 75,   Timestamp: Mon Jul 24 12:29:52 2023
41. Buy ID: 142,        Sell ID: 167,   Price: 102,     Quantity: 25,   Timestamp: Mon Jul 24 12:29:53 2023
42. Buy ID: 145,        Sell ID: 171,   Price: 101.5,   Quantity: 75,   Timestamp: Mon Jul 24 12:29:53 2023
43. Buy ID: 147,        Sell ID: 171,   Price: 101.5,   Quantity: 25,   Timestamp: Mon Jul 24 12:29:53 2023
44. Buy ID: 149,        Sell ID: 175,   Price: 101,     Quantity: 25,   Timestamp: Mon Jul 24 12:29:53 2023
45. Buy ID: 148,        Sell ID: 177,   Price: 101.75,  Quantity: 25,   Timestamp: Mon Jul 24 12:29:53 2023
46. Buy ID: 147,        Sell ID: 178,   Price: 101.5,   Quantity: 25,   Timestamp: Mon Jul 24 12:29:53 2023
47. Buy ID: 151,        Sell ID: 179,   Price: 100.25,  Quantity: 75,   Timestamp: Mon Jul 24 12:29:53 2023
48. Buy ID: 154,        Sell ID: 187,   Price: 101,     Quantity: 75,   Timestamp: Mon Jul 24 12:29:53 2023
49. Buy ID: 153,        Sell ID: 187,   Price: 101,     Quantity: 25,   Timestamp: Mon Jul 24 12:29:53 2023
50. Buy ID: 155,        Sell ID: 188,   Price: 101.5,   Quantity: 50,   Timestamp: Mon Jul 24 12:29:53 2023
51. Buy ID: 156,        Sell ID: 189,   Price: 100.25,  Quantity: 75,   Timestamp: Mon Jul 24 12:29:53 2023
52. Buy ID: 159,        Sell ID: 191,   Price: 101.25,  Quantity: 25,   Timestamp: Mon Jul 24 12:29:54 2023
53. Buy ID: 158,        Sell ID: 194,   Price: 101.75,  Quantity: 100,  Timestamp: Mon Jul 24 12:29:54 2023
54. Buy ID: 160,        Sell ID: 197,   Price: 102,     Quantity: 50,   Timestamp: Mon Jul 24 12:29:54 2023
55. Buy ID: 163,        Sell ID: 198,   Price: 101.75,  Quantity: 50,   Timestamp: Mon Jul 24 12:29:54 2023
56. Buy ID: 177,        Sell ID: 207,   Price: 100,     Quantity: 75,   Timestamp: Mon Jul 24 12:29:54 2023
57. Buy ID: 182,        Sell ID: 209,   Price: 102,     Quantity: 50,   Timestamp: Mon Jul 24 12:29:54 2023
58. Buy ID: 181,        Sell ID: 209,   Price: 102,     Quantity: 25,   Timestamp: Mon Jul 24 12:29:54 2023
59. Buy ID: 183,        Sell ID: 211,   Price: 100.5,   Quantity: 75,   Timestamp: Mon Jul 24 12:29:54 2023
60. Buy ID: 194,        Sell ID: 219,   Price: 100.75,  Quantity: 25,   Timestamp: Mon Jul 24 12:29:55 2023
61. Buy ID: 195,        Sell ID: 221,   Price: 100.5,   Quantity: 25,   Timestamp: Mon Jul 24 12:29:55 2023
62. Buy ID: 203,        Sell ID: 225,   Price: 101.5,   Quantity: 75,   Timestamp: Mon Jul 24 12:29:55 2023
63. Buy ID: 202,        Sell ID: 227,   Price: 101.25,  Quantity: 25,   Timestamp: Mon Jul 24 12:29:55 2023
64. Buy ID: 207,        Sell ID: 237,   Price: 100.75,  Quantity: 25,   Timestamp: Mon Jul 24 12:29:55 2023
65. Buy ID: 209,        Sell ID: 239,   Price: 101.75,  Quantity: 25,   Timestamp: Mon Jul 24 12:29:55 2023
66. Buy ID: 216,        Sell ID: 248,   Price: 100.5,   Quantity: 25,   Timestamp: Mon Jul 24 12:29:55 2023
67. Buy ID: 266,        Sell ID: 287,   Price: 101.75,  Quantity: 25,   Timestamp: Mon Jul 24 12:29:57 2023
68. Buy ID: 271,        Sell ID: 294,   Price: 100.25,  Quantity: 75,   Timestamp: Mon Jul 24 12:29:57 2023
69. Buy ID: 273,        Sell ID: 295,   Price: 102,     Quantity: 75,   Timestamp: Mon Jul 24 12:29:57 2023
70. Buy ID: 276,        Sell ID: 294,   Price: 100.25,  Quantity: 25,   Timestamp: Mon Jul 24 12:29:57 2023
71. Buy ID: 285,        Sell ID: 298,   Price: 101,     Quantity: 25,   Timestamp: Mon Jul 24 12:29:57 2023
72. Buy ID: 305,        Sell ID: 321,   Price: 101.75,  Quantity: 75,   Timestamp: Mon Jul 24 12:29:58 2023
73. Buy ID: 319,        Sell ID: 337,   Price: 101.75,  Quantity: 25,   Timestamp: Mon Jul 24 12:29:58 2023
