Outputs (Seed=227)/Matching Engine Output (Buy greater than Sell).txt
D:\Athul\Quant Development\Matching Engine>g++ matching_engine.cpp -o server.exe -lws2_32 && server.exe
1. Buy ID: 1,   Sell ID: 3,     Price: 100.75,  Quantity: 25,   Timestamp: Mon Jul 24 12:16:43 2023
Total Trades = 3
Engine Profit = 125
2. Buy ID: 1,   Sell ID: 2,     Price: 101.25,  Quantity: 25,   Timestamp: Mon Jul 24 12:16:43 2023
3. Buy ID: 1,   Sell ID: 1,     Price: 100,     Quantity: 50,   Timestamp: Mon Jul 24 12:16:43 2023
4. Buy ID: 2,   Sell ID: 1,     Price: 100,     Quantity: 25,   Timestamp: Mon Jul 24 12:16:43 2023
5. Buy ID: 7,   Sell ID: 5,     Price: 101,     Quantity: 50,   Timestamp: Mon Jul 24 12:16:43 2023
6. Buy ID: 7,   Sell ID: 4,     Price: 101.25,  Quantity: 50,   Timestamp: Mon Jul 24 12:16:43 2023
7. Buy ID: 9,   Sell ID: 4,     Price: 101.25,  Quantity: 50,   Timestamp: Mon Jul 24 12:16:43 2023
8. Buy ID: 9,   Sell ID: 6,     Price: 101.75,  Quantity: 50,   Timestamp: Mon Jul 24 12:16:43 2023
9. Buy ID: 8,   Sell ID: 7,     Price: 100.25,  Quantity: 100,  Timestamp: Mon Jul 24 12:16:43 2023
10. Buy ID: 11,         Sell ID: 8,     Price: 101,     Quantity: 50,   Timestamp: Mon Jul 24 12:16:43 2023
11. Buy ID: 11,         Sell ID: 6,     Price: 101.75,  Quantity: 50,   Timestamp: Mon Jul 24 12:16:43 2023
12. Buy ID: 13,         Sell ID: 9,     Price: 101.5,   Quantity: 25,   Timestamp: Mon Jul 24 12:16:43 2023
13. Buy ID: 13,         Sell ID: 10,    Price: 102,     Quantity: 50,   Timestamp: Mon Jul 24 12:16:43 2023
14. Buy ID: 15,         Sell ID: 11,    Price: 101,     Quantity: 50,   Timestamp: Mon Jul 24 12:16:43 2023
15. Buy ID: 14,         Sell ID: 14,    Price: 100.25,  Quantity: 50,   Timestamp: Mon Jul 24 12:16:43 2023
16. Buy ID: 13,         Sell ID: 14,    Price: 100.25,  Quantity: 25,   Timestamp: Mon Jul 24 12:16:43 2023
17. Buy ID: 12,         Sell ID: 14,    Price: 100.25,  Quantity: 25,   Timestamp: Mon Jul 24 12:16:43 2023
18. Buy ID: 17,         Sell ID: 16,    Price: 100.75,  Quantity: 25,   Timestamp: Mon Jul 24 12:16:43 2023
19. Buy ID: 20,         Sell ID: 19,    Price: 100.75,  Quantity: 25,   Timestamp: Mon Jul 24 12:16:44 2023
20. Buy ID: 20,         Sell ID: 20,    Price: 100.25,  Quantity: 25,   Timestamp: Mon Jul 24 12:16:44 2023
21. Buy ID: 23,         Sell ID: 22,    Price: 101.25,  Quantity: 75,   Timestamp: Mon Jul 24 12:16:44 2023
22. Buy ID: 26,         Sell ID: 23,    Price: 100.5,   Quantity: 25,   Timestamp: Mon Jul 24 12:16:44 2023
23. Buy ID: 27,         Sell ID: 21,    Price: 101,     Quantity: 25,   Timestamp: Mon Jul 24 12:16:44 2023
24. Buy ID: 28,         Sell ID: 24,    Price: 100.25,  Quantity: 50,   Timestamp: Mon Jul 24 12:16:44 2023
25. Buy ID: 26,         Sell ID: 24,    Price: 100.25,  Quantity: 25,   Timestamp: Mon Jul 24 12:16:44 2023
26. Buy ID: 29,         Sell ID: 25,    Price: 100.5,   Quantity: 75,   Timestamp: Mon Jul 24 12:16:44 2023
27. Buy ID: 25,         Sell ID: 31,    Price: 100,     Quantity: 75,   Timestamp: Mon Jul 24 12:16:44 2023
28. Buy ID: 24,         Sell ID: 33,    Price: 100,     Quantity: 50,   Timestamp: Mon Jul 24 12:16:44 2023
29. Buy ID: 30,         Sell ID: 32,    Price: 101.75,  Quantity: 100,  Timestamp: Mon Jul 24 12:16:44 2023
30. Buy ID: 31,         Sell ID: 30,    Price: 100.5,   Quantity: 25,   Timestamp: Mon Jul 24 12:16:44 2023
31. Buy ID: 32,         Sell ID: 30,    Price: 100.5,   Quantity: 50,   Timestamp: Mon Jul 24 12:16:44 2023
32. Buy ID: 35,         Sell ID: 29,    Price: 102,     Quantity: 25,   Timestamp: Mon Jul 24 12:16:44 2023
33. Buy ID: 34,         Sell ID: 34,    Price: 100.5,   Quantity: 25,   Timestamp: Mon Jul 24 12:16:44 2023
34. Buy ID: 33,         Sell ID: 34,    Price: 100.5,   Quantity: 25,   Timestamp: Mon Jul 24 12:16:44 2023
35. Buy ID: 38,         Sell ID: 35,    Price: 101.25,  Quantity: 75,   Timestamp: Mon Jul 24 12:16:44 2023
36. Buy ID: 41,         Sell ID: 37,    Price: 100.5,   Quantity: 75,   Timestamp: Mon Jul 24 12:16:44 2023
37. Buy ID: 40,         Sell ID: 39,    Price: 100,     Quantity: 25,   Timestamp: Mon Jul 24 12:16:44 2023
38. Buy ID: 39,         Sell ID: 39,    Price: 100,     Quantity: 25,   Timestamp: Mon Jul 24 12:16:44 2023
39. Buy ID: 39,         Sell ID: 41,    Price: 100,     Quantity: 25,   Timestamp: Mon Jul 24 12:16:44 2023
40. Buy ID: 38,         Sell ID: 41,    Price: 100,     Quantity: 25,   Timestamp: Mon Jul 24 12:16:44 2023
41. Buy ID: 37,         Sell ID: 41,    Price: 100,     Quantity: 50,   Timestamp: Mon Jul 24 12:16:44 2023
42. Buy ID: 37,         Sell ID: 42,    Price: 100,     Quantity: 50,   Timestamp: Mon Jul 24 12:16:44 2023
43. Buy ID: 36,         Sell ID: 42,    Price: 100,     Quantity: 25,   Timestamp: Mon Jul 24 12:16:44 2023
44. Buy ID: 43,         Sell ID: 43,    Price: 101.25,  Quantity: 100,  Timestamp: Mon Jul 24 12:16:44 2023
45. Buy ID: 44,         Sell ID: 46,    Price: 100.5,   Quantity: 50,   Timestamp: Mon Jul 24 12:16:44 2023
46. Buy ID: 45,         Sell ID: 47,    Price: 101,     Quantity: 25,   Timestamp: Mon Jul 24 12:16:44 2023
47. Buy ID: 46,         Sell ID: 54,    Price: 101,     Quantity: 50,   Timestamp: Mon Jul 24 12:16:45 2023
48. Buy ID: 42,         Sell ID: 55,    Price: 100,     Quantity: 50,   Timestamp: Mon Jul 24 12:16:45 2023
49. Buy ID: 47,         Sell ID: 57,    Price: 101,     Quantity: 75,   Timestamp: Mon Jul 24 12:16:45 2023
50. Buy ID: 48,         Sell ID: 59,    Price: 100.25,  Quantity: 25,   Timestamp: Mon Jul 24 12:16:45 2023
51. Buy ID: 36,         Sell ID: 59,    Price: 100.25,  Quantity: 50,   Timestamp: Mon Jul 24 12:16:45 2023
52. Buy ID: 36,         Sell ID: 60,    Price: 100,     Quantity: 25,   Timestamp: Mon Jul 24 12:16:45 2023
53. Buy ID: 33,         Sell ID: 60,    Price: 100,     Quantity: 50,   Timestamp: Mon Jul 24 12:16:45 2023
54. Buy ID: 32,         Sell ID: 62,    Price: 100.25,  Quantity: 50,   Timestamp: Mon Jul 24 12:16:45 2023
55. Buy ID: 49,         Sell ID: 63,    Price: 101,     Quantity: 50,   Timestamp: Mon Jul 24 12:16:45 2023
56. Buy ID: 50,         Sell ID: 68,    Price: 100.5,   Quantity: 75,   Timestamp: Mon Jul 24 12:16:45 2023
57. Buy ID: 51,         Sell ID: 69,    Price: 101.5,   Quantity: 50,   Timestamp: Mon Jul 24 12:16:45 2023
58. Buy ID: 54,         Sell ID: 72,    Price: 101.5,   Quantity: 50,   Timestamp: Mon Jul 24 12:16:45 2023
59. Buy ID: 58,         Sell ID: 74,    Price: 101.25,  Quantity: 100,  Timestamp: Mon Jul 24 12:16:45 2023
60. Buy ID: 57,         Sell ID: 76,    Price: 100,     Quantity: 25,   Timestamp: Mon Jul 24 12:16:45 2023
61. Buy ID: 56,         Sell ID: 76,    Price: 100,     Quantity: 25,   Timestamp: Mon Jul 24 12:16:45 2023
62. Buy ID: 55,         Sell ID: 76,    Price: 100,     Quantity: 50,   Timestamp: Mon Jul 24 12:16:45 2023
63. Buy ID: 55,         Sell ID: 78,    Price: 100.75,  Quantity: 25,   Timestamp: Mon Jul 24 12:16:45 2023
64. Buy ID: 53,         Sell ID: 78,    Price: 100.75,  Quantity: 25,   Timestamp: Mon Jul 24 12:16:45 2023
65. Buy ID: 59,         Sell ID: 79,    Price: 101.5,   Quantity: 25,   Timestamp: Mon Jul 24 12:16:45 2023
66. Buy ID: 61,         Sell ID: 80,    Price: 101.25,  Quantity: 25,   Timestamp: Mon Jul 24 12:16:45 2023
67. Buy ID: 61,         Sell ID: 79,    Price: 101.5,   Quantity: 50,   Timestamp: Mon Jul 24 12:16:45 2023
68. Buy ID: 62,         Sell ID: 79,    Price: 101.5,   Quantity: 25,   Timestamp: Mon Jul 24 12:16:45 2023
69. Buy ID: 62,         Sell ID: 78,    Price: 100.75,  Quantity: 25,   Timestamp: Mon Jul 24 12:16:45 2023
70. Buy ID: 62,         Sell ID: 77,    Price: 101.25,  Quantity: 25,   Timestamp: Mon Jul 24 12:16:45 2023
71. Buy ID: 63,         Sell ID: 77,    Price: 101.25,  Quantity: 50,   Timestamp: Mon Jul 24 12:16:45 2023
72. Buy ID: 64,         Sell ID: 81,    Price: 101,     Quantity: 50,   Timestamp: Mon Jul 24 12:16:45 2023
73. Buy ID: 65,         Sell ID: 81,    Price: 101,     Quantity: 25,   Timestamp: Mon Jul 24 12:16:45 2023
